<?xml version="1.0" ?>
<!-- =================================================================================== -->
<!-- |    This document was autogenerated by xacro from generated/825fbae9-56fc-40d6-bebb-1cd8a49ffd86.xacro | -->
<!-- |    EDITING THIS FILE BY HAND IS NOT RECOMMENDED                                 | -->
<!-- =================================================================================== -->
<robot name="aly_arm">
  <link name="world"/>
  <joint name="world_joint" type="fixed">
    <parent link="world"/>
    <child link="base_link"/>
    <origin rpy="0 0 0" xyz="0 0 0"/>
  </joint>
  <link name="base_link">
    <visual>
      <geometry>
        <mesh filename="package://aly_arm_0_description/meshes/base_fixture-Body.dae" scale="1 1 1"/>
      </geometry>
    </visual>
    <collision>
      <geometry>
        <mesh filename="package://aly_arm_0_description/meshes/base_fixture-Body.dae" scale="1 1 1"/>
      </geometry>
    </collision>
  </link>
  <joint name="base_holder_joint" type="fixed">
    <parent link="base_link"/>
    <child link="motor_holder_link"/>
    <origin rpy="0 0 0" xyz="0.003 0 0"/>
  </joint>
  <link name="motor_holder_link">
    <visual>
      <geometry>
        <mesh filename="package://aly_arm_0_description/meshes/base_motorholder_90deg_V4-Body.dae" scale="1 1 1"/>
      </geometry>
    </visual>
    <collision>
      <geometry>
        <mesh filename="package://aly_arm_0_description/meshes/base_motorholder_90deg_V4-Body.dae" scale="1 1 1"/>
      </geometry>
    </collision>
  </link>
  <joint name="config_joint_0" type="fixed">
    <parent link="motor_holder_link"/>
    <child link="motor_holder_link_0"/>
    <origin rpy="0 0.0 0" xyz="0 0 0.0804"/>
  </joint>
  <link name="motor_holder_link_0">
    <visual>
      <origin rpy="0 0 0" xyz="0 0 0"/>
      <geometry>
        <mesh filename="package://aly_arm_0_description/meshes/base_motorholder_90deg_V4-Body.dae" scale="1 1 1"/>
      </geometry>
    </visual>
    <collision>
      <origin rpy="0 0 0" xyz="0 0 0"/>
      <geometry>
        <mesh filename="package://aly_arm_0_description/meshes/base_motorholder_90deg_V4-Body.dae" scale="1 1 1"/>
      </geometry>
    </collision>
  </link>
  <joint name="config_joint_1" type="fixed">
    <parent link="motor_holder_link_0"/>
    <child link="link_motor_1"/>
    <origin rpy="0 0.0 0" xyz="0 0 0"/>
  </joint>
  <link name="link_motor_1">
    <visual>
      <origin rpy="1.57 0 0" xyz="0 0 0"/>
      <geometry>
        <mesh filename="package://aly_arm_0_description/meshes/motor_assembly.dae" scale="1 1 1"/>
      </geometry>
    </visual>
    <collision>
      <origin rpy="1.57 0 0" xyz="0 0 0"/>
      <geometry>
        <mesh filename="package://aly_arm_0_description/meshes/motor_assembly.dae" scale="1 1 1"/>
      </geometry>
    </collision>
  </link>
  <joint name="joint_0" type="revolute">
    <parent link="link_motor_1"/>
    <child link="link_active_1"/>
    <origin rpy="0 0.0 0" xyz="0.036 0 0"/>
    <axis xyz="0 0 1"/>
    <limit effort="10.0000" lower="-1.2500" upper="1.2000" velocity="1.0000"/>
  </joint>
  <link name="link_active_1">
    <visual>
      <origin rpy="0 0 0" xyz="0 0 0"/>
      <geometry>
        <mesh filename="package://aly_arm_0_description/meshes/lnk_active_0deg_hirth_18d0_V2_a2plus-Part.dae" scale="1 1 1"/>
      </geometry>
    </visual>
    <collision>
      <origin rpy="0 0 0" xyz="0 0 0"/>
      <geometry>
        <mesh filename="package://aly_arm_0_description/meshes/lnk_active_0deg_hirth_18d0_V2_a2plus-Part.dae" scale="1 1 1"/>
      </geometry>
    </collision>
  </link>
  <joint name="config_joint_2" type="fixed">
    <parent link="link_active_1"/>
    <child link="link_active_2"/>
    <origin rpy="0 0.0 0" xyz="0.036 0 0"/>
  </joint>
  <link name="link_active_2">
    <visual>
      <origin rpy="0 0 0" xyz="0 0 0"/>
      <geometry>
        <mesh filename="package://aly_arm_0_description/meshes/lnk_active_0deg_hirth_18d0_V2_a2plus-Part.dae" scale="1 1 1"/>
      </geometry>
    </visual>
    <collision>
      <origin rpy="0 0 0" xyz="0 0 0"/>
      <geometry>
        <mesh filename="package://aly_arm_0_description/meshes/lnk_active_0deg_hirth_18d0_V2_a2plus-Part.dae" scale="1 1 1"/>
      </geometry>
    </collision>
  </link>
  <joint name="config_joint_3" type="fixed">
    <parent link="link_active_2"/>
    <child link="link_passive_3"/>
    <origin rpy="1.57 0 0" xyz="0.0360 0 0"/>
  </joint>
  <link name="link_passive_3">
    <visual>
      <origin rpy="0 1.57 0" xyz="0 0 0"/>
      <geometry>
        <mesh filename="package://aly_arm_0_description/meshes/lnk_passive_0deg_hirth_18_V3-Body.dae" scale="1 1 1"/>
      </geometry>
    </visual>
    <collision>
      <origin rpy="0 1.57 0" xyz="0 0 0"/>
      <geometry>
        <mesh filename="package://aly_arm_0_description/meshes/lnk_passive_0deg_hirth_18_V3-Body.dae" scale="1 1 1"/>
      </geometry>
    </collision>
  </link>
  <joint name="config_joint_4" type="fixed">
    <parent link="link_passive_3"/>
    <child link="link_motor_4"/>
    <origin rpy="0 0.0 0" xyz="0 0 0"/>
  </joint>
  <link name="link_motor_4">
    <visual>
      <origin rpy="1.57 0 0" xyz="0 0 0"/>
      <geometry>
        <mesh filename="package://aly_arm_0_description/meshes/motor_assembly.dae" scale="1 1 1"/>
      </geometry>
    </visual>
    <collision>
      <origin rpy="1.57 0 0" xyz="0 0 0"/>
      <geometry>
        <mesh filename="package://aly_arm_0_description/meshes/motor_assembly.dae" scale="1 1 1"/>
      </geometry>
    </collision>
  </link>
  <joint name="joint_1" type="revolute">
    <parent link="link_motor_4"/>
    <child link="link_active_4"/>
    <origin rpy="0 0.0 0" xyz="0.036 0 0"/>
    <axis xyz="0 0 1"/>
    <limit effort="10.0000" lower="-1.2500" upper="1.2000" velocity="1.0000"/>
  </joint>
  <link name="link_active_4">
    <visual>
      <origin rpy="0 0 0" xyz="0 0 0"/>
      <geometry>
        <mesh filename="package://aly_arm_0_description/meshes/lnk_active_0deg_hirth_18d0_V2_a2plus-Part.dae" scale="1 1 1"/>
      </geometry>
    </visual>
    <collision>
      <origin rpy="0 0 0" xyz="0 0 0"/>
      <geometry>
        <mesh filename="package://aly_arm_0_description/meshes/lnk_active_0deg_hirth_18d0_V2_a2plus-Part.dae" scale="1 1 1"/>
      </geometry>
    </collision>
  </link>
  <joint name="config_joint_5" type="fixed">
    <parent link="link_active_4"/>
    <child link="link_active_5"/>
    <origin rpy="0 0.0 0" xyz="0.036 0 0"/>
  </joint>
  <link name="link_active_5">
    <visual>
      <origin rpy="0 0 0" xyz="0 0 0"/>
      <geometry>
        <mesh filename="package://aly_arm_0_description/meshes/lnk_active_0deg_hirth_18d0_V2_a2plus-Part.dae" scale="1 1 1"/>
      </geometry>
    </visual>
    <collision>
      <origin rpy="0 0 0" xyz="0 0 0"/>
      <geometry>
        <mesh filename="package://aly_arm_0_description/meshes/lnk_active_0deg_hirth_18d0_V2_a2plus-Part.dae" scale="1 1 1"/>
      </geometry>
    </collision>
  </link>
  <joint name="config_joint_6" type="fixed">
    <parent link="link_active_5"/>
    <child link="link_passive_6"/>
    <origin rpy="1.57 0 0" xyz="0.0360 0 0"/>
  </joint>
  <link name="link_passive_6">
    <visual>
      <origin rpy="0 1.57 0" xyz="0 0 0"/>
      <geometry>
        <mesh filename="package://aly_arm_0_description/meshes/lnk_passive_0deg_hirth_18_V3-Body.dae" scale="1 1 1"/>
      </geometry>
    </visual>
    <collision>
      <origin rpy="0 1.57 0" xyz="0 0 0"/>
      <geometry>
        <mesh filename="package://aly_arm_0_description/meshes/lnk_passive_0deg_hirth_18_V3-Body.dae" scale="1 1 1"/>
      </geometry>
    </collision>
  </link>
  <joint name="config_joint_7" type="fixed">
    <parent link="link_passive_6"/>
    <child link="link_motor_7"/>
    <origin rpy="0 0.0 0" xyz="0 0 0"/>
  </joint>
  <link name="link_motor_7">
    <visual>
      <origin rpy="1.57 0 0" xyz="0 0 0"/>
      <geometry>
        <mesh filename="package://aly_arm_0_description/meshes/motor_assembly_presmatic_joint.dae" scale="1 1 1"/>
      </geometry>
    </visual>
    <collision>
      <origin rpy="1.57 0 0" xyz="0 0 0"/>
      <geometry>
        <mesh filename="package://aly_arm_0_description/meshes/motor_assembly_presmatic_joint.dae" scale="1 1 1"/>
      </geometry>
    </collision>
  </link>
  <joint name="joint_2" type="prismatic">
    <parent link="link_motor_7"/>
    <child link="link_active_7"/>
    <origin rpy="0 0.0 0" xyz="0.036 0 0"/>
    <axis xyz="0 0 1"/>
    <limit effort="10.0000" lower="0.0000" upper="0.0450" velocity="1.0000"/>
  </joint>
  <link name="link_active_7">
    <visual>
      <origin rpy="0 0 0" xyz="0 0 0"/>
      <geometry>
        <mesh filename="package://aly_arm_0_description/meshes/lnk_active_0deg_hirth_18d0_V2_a2plus-Part.dae" scale="1 1 1"/>
      </geometry>
    </visual>
    <collision>
      <origin rpy="0 0 0" xyz="0 0 0"/>
      <geometry>
        <mesh filename="package://aly_arm_0_description/meshes/lnk_active_0deg_hirth_18d0_V2_a2plus-Part.dae" scale="1 1 1"/>
      </geometry>
    </collision>
  </link>
  <joint name="joint_3" type="prismatic">
    <parent link="link_active_7"/>
    <child link="rack_link"/>
    <origin rpy="3.14 -1.57 0" xyz="0.045 -0.030 0.0"/>
    <axis xyz="0 0 1"/>
    <limit effort="10.0000" lower="0.0000" upper="0.0450" velocity="1.0000"/>
  </joint>
  <link name="rack_link">
    <visual>
      <origin rpy="0 0 0" xyz="0 0 0"/>
      <geometry>
        <mesh filename="package://aly_arm_0_description/meshes/rack_assebmly-Part.dae" scale="1 1 1"/>
      </geometry>
    </visual>
    <collision>
      <origin rpy="0 0 0" xyz="0 0 0"/>
      <geometry>
        <mesh filename="package://aly_arm_0_description/meshes/rack_assebmly-Part.dae" scale="1 1 1"/>
      </geometry>
    </collision>
  </link>
  <joint name="config_joint_8" type="fixed">
    <parent link="rack_link"/>
    <child link="pen_holder_link"/>
    <origin rpy="0 0 0.0" xyz="0 0.020 0.022"/>
  </joint>
  <link name="pen_holder_link">
    <visual>
      <origin rpy="0 0 0" xyz="0 0 0"/>
      <geometry>
        <mesh filename="package://aly_arm_0_description/meshes/pen_holder_assembly.dae" scale="1 1 1"/>
      </geometry>
    </visual>
    <collision>
      <origin rpy="0 0 0" xyz="0 0 0"/>
      <geometry>
        <mesh filename="package://aly_arm_0_description/meshes/pen_holder_assembly.dae" scale="1 1 1"/>
      </geometry>
    </collision>
  </link>
</robot>
