<?xml version="1.0"?>
<robot name="aly_arm" xmlns:xacro="http://www.ros.org/wiki/xacro">

  <link name="base_link">
    <visual>
      <geometry>
        <box size="0.1 0.1 0.1"/>
      </geometry>
    </visual>
  </link>
  
  <link name="link_1">
    <visual>
      <geometry>
        <cylinder length="0.2" radius="0.02"/>
      </geometry>
    </visual>
  </link>

  <joint name="joint_1" type="revolute">
    <parent link="base_link"/>
    <child link="link_1"/>
    <origin xyz="0 0 0.2" rpy="0 0 0"/>
    <axis xyz="0 0 1"/>
    <limit lower="-3.14" upper="3.14" effort="10" velocity="1"/>
  </joint>

  
  
  <link name="link_2">
    <visual>
      <geometry>
        <cylinder length="0.15" radius="0.02"/>
      </geometry>
    </visual>
  </link>

  <joint name="joint_2" type="revolute">
    <parent link="base_link"/>
    <child link="link_2"/>
    <origin xyz="0 0 0.15" rpy="0 0 0"/>
    <axis xyz="0 0 1"/>
    <limit lower="-1.57" upper="1.57" effort="10" velocity="1"/>
  </joint>

  
  

</robot>